<?xml version="1.0" ?>

<robot>

<link name="left_wheel_link">
	    <inertial>
	      <origin xyz="0 0 0"/>
	      <mass value="0.01" />
	      <inertia ixx="0.001" ixy="0.0" ixz="0.0"
	        iyy="0.001" iyz="0.0" izz="0.001" />
	    </inertial>
	
	    <visual>
	      <origin xyz="0 0 0" rpy="0 1.5707 1.5707" />
	      <geometry>
	        <cylinder radius="0.033" length = "0.023"/>
	      </geometry>
	    </visual>
	
	    <collision>
	      <origin xyz="0 0 0" rpy="0 1.5707 1.5707" />
	      <geometry>
	        <cylinder radius="0.033" length = "0.023"/>
	      </geometry>
	    </collision>
	  </link>
	
	  <joint name="left_wheel_joint" type="continuous">
	    <origin xyz="0 0.13 0.015" rpy="0 0 0"/>
	    <parent link="base_link"/>
	    <child link="left_wheel_link"/>
	    <axis xyz="0 1 0"/>
	  </joint>
	
	  <link name="right_wheel_link">
	    <inertial>
	      <origin xyz="0 0 0"/>
	      <mass value="0.01" />
	      <inertia ixx="0.001" ixy="0.0" ixz="0.0"
	        iyy="0.001" iyz="0.0" izz="0.001" />
	    </inertial>
	
	    <visual>
	      <origin xyz="0 0 0" rpy="0 1.5707 1.5707" />
	      <geometry>
	        <cylinder radius="0.033" length = "0.023"/>
	      </geometry>
	    </visual>
	
	    <collision>
	      <origin xyz="0 0 0" rpy="0 1.5707 1.5707" />
	      <geometry>
	        <cylinder radius="0.033" length = "0.023"/>
	      </geometry>
	    </collision>
	  </link>
	
	  <joint name="right_wheel_joint" type="continuous">
	    <origin xyz="0 -0.13 0.015" rpy="0 0 0"/>
	    <parent link="base_link"/>
	    <child link="right_wheel_link"/>
	    <axis xyz="0 1 0"/>
	  </joint>
	
	  <link name="rear_wheel_link">
	    <inertial>
	      <origin xyz="0 0 0"/>
	      <mass value="0.001" />
	      <inertia ixx="0.0001" ixy="0.0" ixz="0.0"
	        iyy="0.0001" iyz="0.0" izz="0.0001" />
	    </inertial>
	
	    <visual>
	      <origin xyz="0 0 0" rpy="0 1.5707 1.5707"/>
	      <geometry>
	        <sphere radius="0.015" />
	      </geometry>
	    </visual>
	
	    <collision>
	      <origin xyz="0 0 0" rpy="0 1.5707 1.5707" />
	      <geometry>
	        <sphere radius="0.015" />
	      </geometry>
	    </collision>
	  </link>
	  <!-- fixed because there's no transmission -->
	  <joint name="rear_castor_joint" type="fixed">
	    <origin xyz="-0.13 0 0.0" rpy="0 0 0"/>
	    <parent link="base_link"/>
	    <child link="rear_wheel_link"/>
	    <axis xyz="0 1 0"/>
	  </joint>
	
	  <link name="front_wheel_link">
	    <inertial>
	      <origin xyz="0 0 0" />
	      <mass value="0.01" />
	      <inertia ixx="0.001" ixy="0.0" ixz="0.0"
	        iyy="0.001" iyz="0.0" izz="0.001" />
	    </inertial>
	
	    <visual>
	      <origin xyz="0 0 0" rpy="0 1.5707 1.5707"/>
	      <geometry>
	        <sphere radius="0.018" />
	      </geometry>
	    </visual>
	
	    <collision>
	      <origin xyz="0 0 0" rpy="0 1.5707 1.5707" />
	      <geometry>
	        <sphere radius="0.018" />
	      </geometry>
	    </collision>
	  </link>
	
	  <!-- fixed because there's no transmission -->
	  <joint name="front_castor_joint" type="fixed">
	    <origin xyz="0.13 0 0.0" rpy="0 0 0"/>
	    <parent link="base_link"/>
	    <child link="front_wheel_link"/>
	    <axis xyz="0 1 0"/>
	  </joint>


</robot>