<?xml version="1.0" ?>
<!-- =================================================================================== -->
<!-- |    This document was autogenerated by xacro from tobi_2of4.urdf.xacro           | -->
<!-- |    EDITING THIS FILE BY HAND IS NOT RECOMMENDED                                 | -->
<!-- =================================================================================== -->
<robot name="tobi" xmlns:controller="http://playerstage.sourceforge.net/gazebo/xmlschema/#controller" xmlns:sensor="http://playerstage.sourceforge.net/gazebo/xmlschema/#sensor" xmlns:xacro="http://ros.org/wiki/xacro">
  <link name="guiabot">
    <visual>
      <geometry>
        <mesh filename="package://tobi_description/meshes/guiabot.stl"/>
      </geometry>
      <material name="grey">
        <color rgba="0.5 0.5 0.5 1"/>
      </material>
    </visual>
    <collision>
      <geometry>
        <mesh filename="package://tobi_description/meshes/guiabot.stl"/>
      </geometry>
    </collision>
    <inertial>
      <mass value="2"/>
      <origin xyz="0 0 0"/>
      <inertia ixx="0.4184164993" ixy="0.0" ixz="0.0" iyy="0.43803315812" iyz="0.0" izz="0.0964166281"/>
    </inertial>
  </link>
  <!-- **************************** -->
  <!-- *** Neuronics Katana Arm *** -->
  <!-- **************************** -->
  <!-- transmissions are required by the controller manager (here: for simulation in gazebo) -->
  <transmission name="katana_motor1_pan_trans">
    <type>transmission_interface/SimpleTransmission</type>
    <joint name="katana_motor1_pan_joint">
      <hardwareInterface>EffortJointInterface</hardwareInterface>
    </joint>
    <actuator name="katana_motor1_pan_motor">
      <hardwareInterface>EffortJointInterface</hardwareInterface>
      <mechanicalReduction>1</mechanicalReduction>
    </actuator>
  </transmission>
  <transmission name="katana_motor2_lift_trans">
    <type>transmission_interface/SimpleTransmission</type>
    <joint name="katana_motor2_lift_joint">
      <hardwareInterface>EffortJointInterface</hardwareInterface>
    </joint>
    <actuator name="katana_motor2_lift_motor">
      <hardwareInterface>EffortJointInterface</hardwareInterface>
      <mechanicalReduction>1</mechanicalReduction>
    </actuator>
  </transmission>
  <transmission name="katana_motor3_lift_trans">
    <type>transmission_interface/SimpleTransmission</type>
    <joint name="katana_motor3_lift_joint">
      <hardwareInterface>EffortJointInterface</hardwareInterface>
    </joint>
    <actuator name="katana_motor3_lift_motor">
      <hardwareInterface>EffortJointInterface</hardwareInterface>
      <mechanicalReduction>1</mechanicalReduction>
    </actuator>
  </transmission>
  <transmission name="katana_motor4_lift_trans">
    <type>transmission_interface/SimpleTransmission</type>
    <joint name="katana_motor4_lift_joint">
      <hardwareInterface>EffortJointInterface</hardwareInterface>
    </joint>
    <actuator name="katana_motor4_lift_motor">
      <hardwareInterface>EffortJointInterface</hardwareInterface>
      <mechanicalReduction>1</mechanicalReduction>
    </actuator>
  </transmission>
  <transmission name="katana_motor5_wrist_roll_trans">
    <type>transmission_interface/SimpleTransmission</type>
    <joint name="katana_motor5_wrist_roll_joint">
      <hardwareInterface>EffortJointInterface</hardwareInterface>
    </joint>
    <actuator name="katana_motor5_wrist_roll_motor">
      <hardwareInterface>EffortJointInterface</hardwareInterface>
      <mechanicalReduction>1</mechanicalReduction>
    </actuator>
  </transmission>
  <transmission name="katana_r_finger_trans">
    <type>transmission_interface/SimpleTransmission</type>
    <joint name="katana_r_finger_joint">
      <hardwareInterface>EffortJointInterface</hardwareInterface>
    </joint>
    <actuator name="katana_r_finger_motor">
      <hardwareInterface>EffortJointInterface</hardwareInterface>
      <mechanicalReduction>1</mechanicalReduction>
    </actuator>
  </transmission>
  <transmission name="katana_l_finger_trans">
    <type>transmission_interface/SimpleTransmission</type>
    <joint name="katana_l_finger_joint">
      <hardwareInterface>EffortJointInterface</hardwareInterface>
    </joint>
    <actuator name="katana_l_finger_motor">
      <hardwareInterface>EffortJointInterface</hardwareInterface>
      <mechanicalReduction>1</mechanicalReduction>
    </actuator>
  </transmission>
  <gazebo>
    <plugin filename="libgazebo_ros_control.so" name="gazebo_ros_control">
      <robotSimType>gazebo_ros_control/DefaultRobotHWSim</robotSimType>
    </plugin>
    <!-- gripper controller -->
    <plugin filename="libgazebo_ros_katana_gripper.so" name="katana_gripper_controller">
      <alwaysOn>true</alwaysOn>
      <node_namespace>katana</node_namespace>
      <r_finger_joint>katana_r_finger_joint</r_finger_joint>
      <l_finger_joint>katana_l_finger_joint</l_finger_joint>
      <updateRate>1000.0</updateRate>
      <max_torque>0.5</max_torque>
    </plugin>
    <!-- a formal implementation of grasp hack in gazebo with fixed joint -->
    <gripper name="katana_gripper_grasp_hack">
      <grasp_check>
        <attach_steps>20</attach_steps>
        <detach_steps>40</detach_steps>
        <min_contact_count>2</min_contact_count>
      </grasp_check>
      <gripper_link>katana_r_finger_link</gripper_link>
      <gripper_link>katana_l_finger_link</gripper_link>
      <palm_link>katana_gripper_link</palm_link>
    </gripper>
  </gazebo>
  <!-- NOTE: all gazebo extensions are listed here: simulator_gazebo/gazebo/src/urdf2gazebo.cpp -->
  <!-- all materials are listed here: simulator_gazebo/gazebo/gazebo/share/gazebo/Media/materials/ -->
  <!-- *************** links *************** -->
  <gazebo reference="katana_base_link">
    <material value="Gazebo/Grey"/>
  </gazebo>
  <gazebo reference="katana_motor1_pan_link">
    <material value="Gazebo/Grey"/>
    <turnGravityOff>true</turnGravityOff>
  </gazebo>
  <gazebo reference="katana_motor2_lift_link">
    <material value="Gazebo/Grey"/>
    <turnGravityOff>true</turnGravityOff>
  </gazebo>
  <gazebo reference="katana_motor3_lift_link">
    <material value="Gazebo/Grey"/>
    <turnGravityOff>true</turnGravityOff>
  </gazebo>
  <gazebo reference="katana_motor4_lift_link">
    <material value="Gazebo/Grey"/>
    <turnGravityOff>true</turnGravityOff>
  </gazebo>
  <gazebo reference="katana_motor5_wrist_roll_link">
    <material value="Gazebo/Grey"/>
    <turnGravityOff>true</turnGravityOff>
  </gazebo>
  <gazebo reference="katana_gripper_link">
    <material value="Gazebo/Grey"/>
    <turnGravityOff>true</turnGravityOff>
  </gazebo>
  <!-- TODO: set friction parameters (mu1, mu2, kp, kd) for fingers (see PR2 gripper.gazebo.xacro) -->
  <gazebo reference="katana_r_finger_link">
    <material value="Gazebo/Grey"/>
    <turnGravityOff>true</turnGravityOff>
  </gazebo>
  <!-- TODO: set friction parameters (mu1, mu2, kp, kd) for fingers (see PR2 gripper.gazebo.xacro) -->
  <gazebo reference="katana_l_finger_link">
    <material value="Gazebo/Grey"/>
    <turnGravityOff>true</turnGravityOff>
  </gazebo>
  <!-- *************** joints ************** -->
  <!-- note: initial_joint_position isn't supported by Gazebo yet

  <gazebo reference="katana_motor1_pan_joint">
    <initial_joint_position>-3.022</initial_joint_position>
  </gazebo>

  <gazebo reference="katana_motor2_lift_joint">
    <initial_joint_position>2.163</initial_joint_position>
  </gazebo>

  <gazebo reference="katana_motor3_lift_joint">
    <initial_joint_position>-2.207</initial_joint_position>
  </gazebo>

  <gazebo reference="katana_motor4_lift_joint">
    <initial_joint_position>-2.026</initial_joint_position>
  </gazebo>

  <gazebo reference="katana_motor5_wrist_roll_joint">
    <initial_joint_position>-2.990</initial_joint_position>
  </gazebo>

  <xacro:macro name="gazebo_finger_joint" params="prefix">
    <gazebo reference="katana_${prefix}_finger_joint">
      <initial_joint_position>0.3</initial_joint_position>
    </gazebo>
  </xacro:macro>

  <xacro:gazebo_finger_joint prefix="r"/>
  <xacro:gazebo_finger_joint prefix="l"/>
  -->
  <!-- All inertial values (mass, center of mass and inertia tensor) have been
  calculated from the meshes using MeshLab -->
  <!-- lower + upper joint limits have been calculated using the KNI's GetEncoderMinPos(), GetEncoderMaxPos();
  the velocity limit has been calculated by vel_enc2rad(180); 180 encoders / 10ms is the maximum
  speed limit for all joints, according to the Katana 4D documentation -->
  <!-- the effort limits have been measured experimentally from the maximum effort the Gazebo controller 
  uses in normal conditions -->
  <link name="katana_base_link">
    <visual>
      <origin rpy="0 0 0" xyz="0 0 0"/>
      <geometry>
        <mesh filename="package://katana_description/meshes/katana/katana_base_link.stl"/>
      </geometry>
      <material name="grey">
        <color rgba="0.8 0.8 0.8 1"/>
      </material>
    </visual>
    <collision>
      <origin rpy="0 0 0" xyz="0 0 0.1"/>
      <geometry>
        <cylinder length="0.20" radius="0.045"/>
      </geometry>
    </collision>
    <inertial>
      <mass value="1.4047990875"/>
      <origin xyz="-0.000327 0.000908 0.058457"/>
      <inertia ixx="0.003000703" ixy="0.000000864" ixz="-0.000011312" iyy="0.002974822" iyz="0.000036294" izz="0.001434739"/>
    </inertial>
  </link>
  <joint name="katana_motor1_pan_joint" type="revolute">
    <!-- Joint 1 in Katana Manual -->
    <parent link="katana_base_link"/>
    <child link="katana_motor1_pan_link"/>
    <origin rpy="0 0 0" xyz="0 0 0.2015"/>
    <axis xyz="0 0 1"/>
    <limit effort="1.5" lower="-3.0229511" upper="3.0123429" velocity="2.208932"/>
  </joint>
  <link name="katana_motor1_pan_link">
    <visual>
      <origin rpy="0 0 0" xyz="0 0 -0.2015"/>
      <geometry>
        <mesh filename="package://katana_description/meshes/katana/katana_motor1_pan_link.stl"/>
      </geometry>
      <material name="grey"/>
    </visual>
    <collision>
      <origin rpy="1.57079632679 0 0" xyz="0 0 0"/>
      <geometry>
        <cylinder length="0.085" radius="0.047"/>
      </geometry>
    </collision>
    <collision>
      <origin rpy="1.57079632679 0 0" xyz="0 0 0"/>
      <geometry>
        <cylinder length="0.13" radius="0.03"/>
      </geometry>
    </collision>
    <inertial>
      <mass value="0.74793301875"/>
      <origin xyz="-0.000410 -0.001285 -0.016774"/>
      <inertia ixx="0.001737241" ixy="0.000000421" ixz="0.000000650" iyy="0.000998782" iyz="0.000016114" izz="0.001349170"/>
    </inertial>
  </link>
  <joint name="katana_motor2_lift_joint" type="revolute">
    <!-- Joint 2 in Katana Manual -->
    <parent link="katana_motor1_pan_link"/>
    <child link="katana_motor2_lift_link"/>
    <origin rpy="1.57079632679 0 0" xyz="0 0 0"/>
    <axis xyz="0 0 1"/>
    <limit effort="0.6" lower="-2.6012933" upper="2.1639407" velocity="1.190799"/>
  </joint>
  <link name="katana_motor2_lift_link">
    <visual>
      <origin rpy="-1.57079632679 0 0" xyz="0 0 0"/>
      <geometry>
        <mesh filename="package://katana_description/meshes/katana/katana_motor2_lift_link.stl"/>
      </geometry>
      <!-- <geometry>
	  <cylinder length="${link2_length}" radius="0.02"/>
	  </geometry>
	  <origin rpy="0 ${-M_PI/2} 0" xyz="${link2_length/2} 0 0" /> -->
      <material name="grey"/>
    </visual>
    <collision>
      <origin rpy="0 1.57079632679 0" xyz="0.09 0 0"/>
      <geometry>
        <cylinder length="0.18" radius="0.02"/>
      </geometry>
    </collision>
    <collision>
      <origin rpy="0 0 0" xyz="0.095 0.0 -0.025"/>
      <geometry>
        <box size="0.04 0.04 0.085"/>
      </geometry>
    </collision>
    <inertial>
      <mass value="0.80174941875"/>
      <origin xyz="0.092420 0.005283 0.000172"/>
      <inertia ixx="0.000478252" ixy="0.000081166" ixz="0.000003961" iyy="0.004314636" iyz="0.000000332" izz="0.004625444"/>
    </inertial>
  </link>
  <joint name="katana_motor3_lift_joint" type="revolute">
    <!-- Joint 3 in Katana Manual -->
    <parent link="katana_motor2_lift_link"/>
    <child link="katana_motor3_lift_link"/>
    <origin rpy="0 0 0" xyz="0.19 0 0"/>
    <axis xyz="0 0 1"/>
    <!-- unexplicably, the measured velocity limit of this motor is exactly half of what vel_enc2rad(180) says -->
    <limit effort="0.25" lower="-2.1833017" upper="2.149487" velocity="1.190799"/>
  </joint>
  <link name="katana_motor3_lift_link">
    <visual>
      <origin rpy="-1.57079632679 0 0" xyz="0 0 0"/>
      <geometry>
        <mesh filename="package://katana_description/meshes/katana/katana_motor3_lift_link.stl"/>
      </geometry>
      <!--<geometry>
	    <cylinder length="${link3_length}" radius="0.02"/>
	    </geometry>
	    <origin rpy="0 ${-M_PI/2} 0" xyz="${link3_length/2} 0 0" />-->
      <material name="grey"/>
    </visual>
    <collision>
      <origin rpy="0 0 0" xyz="0.0 0 0"/>
      <geometry>
        <cylinder length="0.075" radius="0.04"/>
      </geometry>
    </collision>
    <collision>
      <origin rpy="0 0 0" xyz="0.0 0 0"/>
      <geometry>
        <cylinder length="0.125" radius="0.025"/>
      </geometry>
    </collision>
    <collision>
      <origin rpy="0 0 0" xyz="0.05 0.0 -0.05"/>
      <geometry>
        <box size="0.04 0.04 0.08"/>
      </geometry>
    </collision>
    <collision>
      <origin rpy="0 0 0" xyz="0.035 0 0"/>
      <geometry>
        <cylinder length="0.075" radius="0.037"/>
      </geometry>
    </collision>
    <collision>
      <origin rpy="0 1.57079632679 0" xyz="0.06 0 0"/>
      <geometry>
        <cylinder length="0.12" radius="0.02"/>
      </geometry>
    </collision>
    <inertial>
      <mass value="0.79241664375"/>
      <origin xyz="0.058036 0.008963 -0.000187"/>
      <inertia ixx="0.001156089" ixy="0.000112877" ixz="-0.000004398" iyy="0.002305646" iyz="-0.000000036" izz="0.003128648"/>
    </inertial>
  </link>
  <joint name="katana_motor4_lift_joint" type="revolute">
    <!-- Joint 4 in Katana Manual -->
    <parent link="katana_motor3_lift_link"/>
    <child link="katana_motor4_lift_link"/>
    <origin rpy="3.14159265359 0 0" xyz="0.139 0 0"/>
    <axis xyz="0 0 1"/>
    <limit effort="0.1" lower="-2.030977" upper="1.9919797" velocity="2.208932"/>
  </joint>
  <link name="katana_motor4_lift_link">
    <visual>
      <origin rpy="1.57079632679 0 0" xyz="0 0 0"/>
      <geometry>
        <mesh filename="package://katana_description/meshes/katana/katana_motor4_lift_link.stl"/>
      </geometry>
      <!-- <geometry>
	      <cylinder length="${link4_length}" radius="0.02"/>
	      </geometry>
	      <origin rpy="0 ${-M_PI/2} 0" xyz="${link4_length/2} 0 0" /> -->
      <material name="grey"/>
    </visual>
    <collision>
      <origin rpy="0 0 0" xyz="0.0 0 0"/>
      <geometry>
        <cylinder length="0.06" radius="0.038"/>
      </geometry>
    </collision>
    <collision>
      <origin rpy="0 0 0" xyz="0.0 0 0"/>
      <geometry>
        <cylinder length="0.11" radius="0.024"/>
      </geometry>
    </collision>
    <collision>
      <origin rpy="0 0 0" xyz="0.042 0.0 0.05"/>
      <geometry>
        <box size="0.02 0.04 0.07"/>
      </geometry>
    </collision>
    <collision>
      <origin rpy="0 0 0" xyz="0.035 0 0"/>
      <geometry>
        <cylinder length="0.065" radius="0.038"/>
      </geometry>
    </collision>
    <collision>
      <origin rpy="0 1.57079632679 0" xyz="0.09 0 0"/>
      <geometry>
        <cylinder length="0.07" radius="0.03"/>
      </geometry>
    </collision>
    <inertial>
      <mass value="0.69149323125"/>
      <origin xyz="0.050401 0.005807 0.000000"/>
      <inertia ixx="0.000765999" ixy="0.000045260" ixz="-0.000001210" iyy="0.001504115" iyz="0.000000147" izz="0.001887277"/>
    </inertial>
  </link>
  <joint name="katana_motor5_wrist_roll_joint" type="revolute">
    <!-- Joint 5 in Katana Manual -->
    <parent link="katana_motor4_lift_link"/>
    <child link="katana_motor5_wrist_roll_link"/>
    <origin rpy="1.57079632679 0 -1.57079632679" xyz="0.1473 0 0"/>
    <axis xyz="0 0 1"/>
    <limit effort="0.01" lower="-2.29926262" upper="3.016518" velocity="2.208932"/>
  </joint>
  <link name="katana_motor5_wrist_roll_link">
    <visual>
      <origin rpy="0 0 0" xyz="0 0 0"/>
      <geometry>
        <mesh filename="package://katana_description/meshes/katana/katana_motor5_wrist_roll_link.stl"/>
      </geometry>
      <!--<geometry>
		<cylinder length="${link5_length}" radius="0.02"/>
		</geometry>
		<origin rpy="0 ${-M_PI/2} 0" xyz="${link5_length/2} 0 0" />-->
      <material name="grey"/>
    </visual>
    <collision>
      <origin rpy="0 0 0" xyz="0 0 0"/>
      <geometry>
        <cylinder length="0.07" radius="0.024"/>
      </geometry>
    </collision>
    <collision>
      <origin rpy="0 1.57079632679 0" xyz="-0.036 0 0"/>
      <geometry>
        <cylinder length="0.028" radius="0.023"/>
      </geometry>
    </collision>
    <inertial>
      <mass value="0.25622555625"/>
      <origin xyz="-0.003140899 0.000013920 0.001680144"/>
      <inertia ixx="0.000120481" ixy="0.000000015" ixz="-0.000001089" iyy="0.000132130" iyz="-0.000000124" izz="0.000093522"/>
    </inertial>
  </link>
  <joint name="katana_gripper_joint" type="fixed">
    <parent link="katana_motor5_wrist_roll_link"/>
    <child link="katana_gripper_link"/>
    <origin rpy="0 1.57079632679 0" xyz="0 0 -0.0323"/>
    <origin rpy="0 1.57079632679 0" xyz="0 0 -0.0323"/>
  </joint>
  <link name="katana_gripper_link">
    <visual>
      <origin rpy="0 3.14159265359 0" xyz="0 0 0"/>
      <geometry>
        <mesh filename="package://katana_description/meshes/katana/katana_gripper_link.stl"/>
      </geometry>
      <material name="grey"/>
    </visual>
    <collision>
      <origin rpy="0 1.57079632679 0" xyz="0.015 0 0"/>
      <geometry>
        <cylinder length="0.03" radius="0.018"/>
      </geometry>
    </collision>
    <collision>
      <origin rpy="0 1.57079632679 0" xyz="0.04 0 0"/>
      <geometry>
        <cylinder length="0.02" radius="0.014"/>
      </geometry>
    </collision>
    <inertial>
      <mass value="0.0552136183596"/>
      <origin xyz="-0.014379 -0.000000 0.000006"/>
      <inertia ixx="0.000011468" ixy="0.000000000" ixz="0.000000007" iyy="0.000013830" iyz="0.000000000" izz="0.000011290"/>
    </inertial>
  </link>
  <joint name="katana_r_finger_joint" type="revolute">
    <parent link="katana_gripper_link"/>
    <child link="katana_r_finger_link"/>
    <origin rpy="0 0 0" xyz="0.034 0 0"/>
    <axis xyz="0 0 1"/>
    <limit effort="0.5" lower="-0.60" upper="0.30" velocity="0.718834"/>
  </joint>
  <link name="katana_r_finger_link">
    <visual>
      <origin rpy="0 3.14159265359 0" xyz="0 0 0"/>
      <geometry>
        <mesh filename="package://katana_description/meshes/katana/katana_gripper_r_finger.stl"/>
      </geometry>
      <material name="grey"/>
    </visual>
    <collision>
      <origin rpy="0 0 0.589048622548" xyz="0.03 0.03 0"/>
      <geometry>
        <box size="0.06 0.015 0.02"/>
      </geometry>
    </collision>
    <collision>
      <origin rpy="0 0 -0.490873852123" xyz="0.06 0.04 0"/>
      <geometry>
        <box size="0.022 0.012 0.02"/>
      </geometry>
    </collision>
    <collision>
      <origin rpy="0 0 0.392699081699" xyz="0.074 0.04 0"/>
      <geometry>
        <box size="0.021 0.012 0.02"/>
      </geometry>
    </collision>
    <inertial>
      <mass value="0.0251722230462"/>
      <origin xyz="0.001784 0.025167 -.001603"/>
      <inertia ixx="0.000005990" ixy="0.000008473" ixz="0.000001448" iyy="0.000019757" iyz="-0.000000996" izz="0.000023588"/>
    </inertial>
  </link>
  <joint name="katana_l_finger_joint" type="revolute">
    <parent link="katana_gripper_link"/>
    <child link="katana_l_finger_link"/>
    <origin rpy="3.14159265359 0 0" xyz="0.034 0 0"/>
    <axis xyz="0 0 1"/>
    <limit effort="0.5" lower="-0.60" upper="0.30" velocity="0.718834"/>
  </joint>
  <link name="katana_l_finger_link">
    <visual>
      <origin rpy="0 3.14159265359 0" xyz="0 0 0"/>
      <geometry>
        <mesh filename="package://katana_description/meshes/katana/katana_gripper_l_finger.stl"/>
      </geometry>
      <material name="grey"/>
    </visual>
    <collision>
      <origin rpy="0 0 0.589048622548" xyz="0.03 0.03 0"/>
      <geometry>
        <box size="0.06 0.015 0.02"/>
      </geometry>
    </collision>
    <collision>
      <origin rpy="0 0 -0.490873852123" xyz="0.06 0.04 0"/>
      <geometry>
        <box size="0.022 0.012 0.02"/>
      </geometry>
    </collision>
    <collision>
      <origin rpy="0 0 0.392699081699" xyz="0.074 0.04 0"/>
      <geometry>
        <box size="0.021 0.012 0.02"/>
      </geometry>
    </collision>
    <inertial>
      <mass value="0.0251722230462"/>
      <origin xyz="0.001784 0.025167 -.001603"/>
      <inertia ixx="0.000005990" ixy="0.000008473" ixz="0.000001448" iyy="0.000019757" iyz="-0.000000996" izz="0.000023588"/>
    </inertial>
  </link>
  <joint name="katana_gripper_tool_frame_joint" type="fixed">
    <parent link="katana_motor5_wrist_roll_link"/>
    <child link="katana_gripper_tool_frame"/>
    <origin rpy="0 1.57079632679 0" xyz="0 0 -0.11"/>
  </joint>
  <link name="katana_gripper_tool_frame">
    <!-- This is the coordinate system of the end effector (this is the position
		    used in IK); there is no actual arm part attached to this link -->
    <!-- The fake geometry here is only present to work around https://github.com/ros-planning/moveit_core/issues/158 -->
    <visual>
      <origin rpy="0 0 0" xyz="-0.11 0 0"/>
      <geometry>
        <box size="0.01 0.01 0.01"/>
      </geometry>
      <material name="grey"/>
    </visual>
    <collision>
      <origin rpy="0 0 0" xyz="-0.11 0 0"/>
      <geometry>
        <box size="0.01 0.01 0.01"/>
      </geometry>
      <material name="grey"/>
    </collision>
    <inertial>
      <mass value="0.0012"/>
      <origin xyz="0 0 0"/>
      <inertia ixx="2e-8" ixy="0.0" ixz="0.0" iyy="2e-8" iyz="0.0" izz="2e-8"/>
    </inertial>
  </link>
  <joint name="katana_gripper_tool_agni_frame_joint" type="fixed">
    <parent link="katana_motor5_wrist_roll_link"/>
    <child link="katana_gripper_tool_agni_frame"/>
    <origin rpy="0 3.14159265359 0" xyz="0 0 -0.11"/>
  </joint>
  <link name="katana_gripper_tool_agni_frame">
    <!-- This is the coordinate system of the end effector (this is the position
		    used in IK); there is no actual arm part attached to this link -->
    <!-- The fake geometry here is only present to work around https://github.com/ros-planning/moveit_core/issues/158 -->
    <visual>
      <origin rpy="0 0 0" xyz="0 0 -0.11"/>
      <geometry>
        <box size="0.01 0.01 0.01"/>
      </geometry>
      <material name="grey"/>
    </visual>
    <collision>
      <origin rpy="0 0 0" xyz="0 0 -0.11"/>
      <geometry>
        <box size="0.01 0.01 0.01"/>
      </geometry>
      <material name="grey"/>
    </collision>
    <inertial>
      <mass value="0.0012"/>
      <origin xyz="0 0 0"/>
      <inertia ixx="2e-8" ixy="0.0" ixz="0.0" iyy="2e-8" iyz="0.0" izz="2e-8"/>
    </inertial>
  </link>
  <joint name="tobi_guiabot_katana_joint" type="fixed">
    <parent link="guiabot"/>
    <child link="katana_base_link"/>
    <origin rpy="0 -1.57079632679 0" xyz="0.012 0 0.867"/>
  </joint>
  <link name="base_link"/>
  <joint name="base_link_to_guiabot" type="fixed">
    <parent link="base_link"/>
    <child link="guiabot"/>
    <origin rpy="0 0 3.14159265359" xyz="0 0 0"/>
  </joint>
  <link name="box_head_link">
    <visual>
      <geometry>
        <box size="0.1 .1 .1"/>
      </geometry>
      <material name="grey">
        <color rgba="0.5 0.5 0.5 1"/>
      </material>
    </visual>
    <visual>
      <origin rpy="0 -0.56 0" xyz="0.125 0.165 -0.03"/>
      <geometry>
        <cylinder length="0.25" radius="0.017"/>
      </geometry>
      <material name="grey">
        <color rgba="0.2 0.2 0.2 1"/>
      </material>
    </visual>
    <visual>
      <origin rpy="0 -0.56 0" xyz="0.125 -0.165 -0.03"/>
      <geometry>
        <cylinder length="0.25" radius="0.017"/>
      </geometry>
      <material name="grey">
        <color rgba="0.2 0.2 0.2 1"/>
      </material>
    </visual>
    <visual>
      <origin rpy="0 0.08 0" xyz="0.16 0 -0.15"/>
      <geometry>
        <box size="0.04 0.35 0.08"/>
      </geometry>
      <material name="grey">
        <color rgba="0.5 0.5 0.5 1"/>
      </material>
    </visual>
    <collision>
      <geometry>
        <box size="0.1 .1 .1"/>
      </geometry>
    </collision>
    <collision>
      <origin rpy="0 -0.56 0" xyz="0.125 0.165 -0.03"/>
      <geometry>
        <cylinder length="0.25" radius="0.017"/>
      </geometry>
    </collision>
    <collision>
      <origin rpy="0 -0.56 0" xyz="0.125 -0.165 -0.03"/>
      <geometry>
        <cylinder length="0.25" radius="0.017"/>
      </geometry>
    </collision>
    <collision>
      <origin rpy="0 0.08 0" xyz="0.16 0 -0.15"/>
      <geometry>
        <box size="0.04 0.35 0.08"/>
      </geometry>
    </collision>
  </link>
  <joint name="katana_link_to_box_head" type="fixed">
    <parent link="guiabot"/>
    <child link="box_head_link"/>
    <origin rpy="0 0 3.14159265359" xyz="0 0 1.16"/>
  </joint>
  <link name="sensor_head_link">
    <visual>
      <geometry>
        <box size="0.15 .26 .12"/>
      </geometry>
      <material name="grey">
        <color rgba="0.5 0.5 0.5 1"/>
      </material>
    </visual>
    <collision>
      <geometry>
        <box size="0.15 .26 .12"/>
      </geometry>
    </collision>
  </link>
  <joint name="box_head_to_sensor_head" type="fixed">
    <parent link="box_head_link"/>
    <child link="sensor_head_link"/>
    <origin rpy="0 0 0" xyz="0.08 0.02 0.20"/>
  </joint>
</robot>

